Workbook
Name Bollywood: Source_lists!$B$2:$B$13
Name data: Table16[]
Name Hollywood: Source_lists!$C$2:$C$10
Name Marvel_studios: Source_lists!$D$2:$D$9
Name release_date: Table11[#All]
Name release_date: Table11[#All]
Name release_date: Table11[#All]
Name release_date: Table11[#All]
Name Vinod_Chopra_Films: Source_lists!$D$42:$D$44

Sheet Source
A1: movie_id_title | B1: industry | C1: release_year | D1: imdb_rating | E1: studio | F1: language_id
A2: 101:K.G.F: Chapter 2 | B2: Bollywood | C2: 2022 | D2: 8.4 | E2: Hombale Films | F2: 3
A3: 102:Doctor Strange in the Multiverse of Madness | B3: Hollywood | C3: 2022 | D3: 7 | E3: Marvel Studios | F3: 5
A4: 103:Thor: The Dark World | B4: Hollywood | C4: 2013 | D4: 6.8 | E4: Marvel Studios | F4: 5
A5: 104:Thor: Ragnarok | B5: Hollywood | C5: 2017 | D5: 7.9 | E5: Marvel Studios | F5: 5
A6: 105:Thor: Love and Thunder | B6: Hollywood | C6: 2022 | D6: 6.8 | E6: Marvel Studios | F6: 5
A7: 106:Sholay | B7: Bollywood | C7: 1975 | D7: 8.1 | E7: United Producers | F7: 1
A8: 107:Dilwale Dulhania Le Jayenge | B8: Bollywood | C8: 1995 | D8: 8 | E8: Yash Raj Films | F8: 1
A9: 108: 3 Idiots | B9: Bollywood | C9: 2009 | D9: 8.4 | E9: Vinod Chopra Films | F9: 1
A10: 109:Kabhi Khushi Kabhie Gham | B10: Bollywood | C10: 2001 | D10: 7.4 | E10: Dharma Productions | F10: 1
A11: 110:Bajirao Mastani | B11: Bollywood | C11: 2015 | D11: 7.2 | F11: 1
A12: 111: The Shawshank Redemption | B12: Hollywood | C12: 1994 | D12: 9.3 | E12: Castle Rock Entertainment | F12: 5
A13: 112:Inception | B13: Hollywood | C13: 2010 | D13: 8.8 | E13: Warner Bros. Pictures | F13: 5
A14: 113:Interstellar | B14: Hollywood | C14: 2014 | D14: 8.6 | E14: Warner Bros. Pictures | F14: 5
A15: 115:The Pursuit of Happyness | B15: Hollywood | C15: 2006 | D15: 8 | E15: Columbia Pictures | F15: 5
A16: 116:Gladiator | B16: Hollywood | C16: 2000 | D16: 8.5 | E16: Universal Pictures | F16: 5
A17: 117:Titanic | B17: Hollywood | C17: 1997 | D17: 7.9 | E17: Paramount Pictures | F17: 5
A18: 118:It's a Wonderful Life | B18: Hollywood | C18: 1946 | D18: 8.6 | E18: Liberty Films | F18: 5
A19: 119:Avatar | B19: Hollywood | C19: 2009 | D19: 7.8 | E19: 20th Century Fox | F19: 5
A20: 120:The Godfather | B20: Hollywood | C20: 1972 | D20: 9.2 | E20: Paramount Pictures | F20: 5
A21: 121:The Dark Knight | B21: Hollywood | C21: 2008 | D21: 9 | E21: Syncopy | F21: 5
A22: 122:Schindler's List | B22: Hollywood | C22: 1993 | D22: 9 | E22: Universal Pictures | F22: 5
A23: 123:Jurassic Park | B23: Hollywood | C23: 1993 | D23: 8.2 | E23: Universal Pictures | F23: 5
A24: 124:Parasite | B24: Hollywood | C24: 2019 | D24: 8.5 | F24: 5
A25: 125:Avengers: Endgame | B25: Hollywood | C25: 2019 | D25: 8.4 | E25: Marvel Studios | F25: 5
A26: 126:Avengers: Infinity War | B26: Hollywood | C26: 2018 | D26: 8.4 | E26: Marvel Studios | F26: 5
A27: 127:Pather Panchali | B27: Bollywood | C27: 1955 | D27: 8.3 | E27: Government of West Bengal | F27: 7
A28: 128:Taare Zameen Par | B28: Bollywood | C28: 2007 | D28: 8.3 | F28: 1
A29: 129:Munna Bhai M.B.B.S. | B29: Bollywood | C29: 2003 | D29: 8.1 | E29: Vinod Chopra Productions | F29: 1
A30: 124:Parasite | B30: Hollywood | C30: 2019 | D30: 8.5 | F30: 5
A31: 105:Thor: Love and Thunder | B31: Hollywood | C31: 2022 | D31: 6.8 | E31: Marvel Studios | F31: 5
A32: 130:PK | B32: Bollywood | C32: 2014 | D32: 8.1 | E32: Vinod Chopra Films | F32: 1
A33: 131:Sanju | B33: Bollywood | C33: 2018 | D33: NULL | E33: Vinod Chopra Films | F33: 1
A34: 132:Pushpa: The Rise - Part 1 | B34: Bollywood | C34: 2021 | D34: 7.6 | E34: Mythri Movie Makers | F34: 2
A35: 133:RRR | B35: Bollywood | C35: 2022 | D35: 8 | E35: DVV Entertainment | F35: 2
A36: 134:Baahubali: The Beginning | B36: Bollywood | C36: 2015 | D36: 8 | E36: Arka Media Works | F36: 2
A37: 135:The Kashmir Files | B37: Bollywood | C37: 2022 | D37: 8.3 | E37: Zee Studios | F37: 1
A38: 136:Bajrangi Bhaijaan | B38: Bollywood | C38: 2015 | D38: 8.1 | E38: Salman Khan Films | F38: 1
A39: 137:Captain America: The First Avenger | B39: Hollywood | C39: 2011 | D39: 6.9 | E39: Marvel Studios | F39: 5
A40: 138:Captain America: The Winter Soldier | B40: Hollywood | C40: 2014 | D40: 7.8 | E40: Marvel Studios | F40: 5
...

Sheet Financials (2)
A1: movie_id | B1: budget | C1: revenue | D1: unit | E1: currency
A2: 101 | B2: 1 | C2: 12.5 | D2: Billions | E2: INR
A3: 102 | B3: 200 | C3: 954.8 | D3: Millions | E3: USD
A4: 103 | B4: 165 | C4: 644.8 | D4: Millions | E4: USD
A5: 104 | B5: 180 | C5: 854 | D5: Millions | E5: USD
A6: 105 | B6: 250 | C6: 670 | D6: Millions | E6: USD
A7: 107 | B7: 400 | C7: 2000 | D7: Millions | E7: INR
A8: 108 | B8: 550 | C8: 4000 | D8: Millions | E8: INR
A9: 109 | B9: 390 | C9: 1360 | D9: Millions | E9: INR
A10: 110 | B10: 1.4 | C10: 3.5 | D10: Billions | E10: INR
A11: 111 | B11: 25 | C11: 73.3 | D11: Millions | E11: USD
A12: 113 | B12: 165 | C12: 701.8 | D12: Millions | E12: USD
A13: 114 | B13: 205 | C13: 365.3 | D13: Millions | E13: USD
... A41: 412 | B41: 160 | C41: 836.8 | D41: Millions | E41: USD

Sheet financials
A1: movie_id | B1: budget | C1: revenue | D1: unit | E1: currency
A2: 101 | B2: 1 | C2: 12.5 | D2: Billions | E2: INR
A3: 102 | B3: 200 | C3: 954.8 | D3: Millions | E3: USD
A4: 103 | B4: 165 | C4: 644.8 | D4: Millions | E4: USD
A5: 104 | B5: 180 | C5: 854 | D5: Millions | E5: USD
A6: 105 | B6: 250 | C6: 670 | D6: Millions | E6: USD
A7: 107 | B7: 400 | C7: 2000 | D7: Millions | E7: INR
A8: 108 | B8: 550 | C8: 4000 | D8: Millions | E8: INR
A9: 109 | B9: 390 | C9: 1360 | D9: Millions | E9: INR
A10: 110 | B10: 1.4 | C10: 3.5 | D10: Billions | E10: INR
A11: 111 | B11: 25 | C11: 73.3 | D11: Millions | E11: USD
A12: 113 | B12: 165 | C12: 701.8 | D12: Millions | E12: USD
A13: 114 | B13: 205 | C13: 365.3 | D13: Millions | E13: USD
... A41: 412 | B41: 160 | C41: 836.8 | D41: Millions | E41: USD

Sheet release_date
A1: Title | B1: release_date
A2: K.G.F: Chapter 2 | B2: 44665
A3: Doctor Strange in the Multiverse of Madness | B3: 44687
A4: Thor: The Dark World | B4: 41586
A5: Thor: Ragnarok | B5: 43042
A6: Thor: Love and Thunder | B6: 44750
A7: Sholay | B7: 27621
A8: Dilwale Dulhania Le Jayenge | B8: 34992
A9: 3 Idiots | B9: 40172
A10: Kabhi Khushi Kabhie Gham | B10: 37239
A11: Bajirao Mastani | B11: 42356
A12: The Shawshank Redemption | B12: 34600
A13: Inception | B13: 40489
... A42: Shershaah | B42: 44420

Sheet DAY 1
A1: Movie_id | B1: Title | C1: release_year | D1: industry | E1: release_year2 | F1: imdb_rating | G1: studio | H1: language_id | I1: Xlookup Budget | J1: Vlookup Budget | K1: Revenue | L1: unit | M1: status
A2: 101 | B2: K.G.F: Chapter 2 | C2: 2022 | D2: Bollywood | E2: 2022 | F2: 8.4 | G2: Hombale Films | H2: 3 | I2: =_xlfn.XLOOKUP(Movies_1[[#This Row],[Movie_id]],Financials[movie_id],Financials[budget],"not Avialable") -> 1 | J2: =VLOOKUP(Movies_1[[#This Row],[Movie_id]],Financials[],2,FALSE) -> 1 | K2: =_xlfn.XLOOKUP(Movies_1[[#This Row],[Movie_id]],Financials[movie_id],Financials[revenue],"not avialable") -> 12.5 | L2: =_xlfn.XLOOKUP(Movies_1[[#This Row],[Movie_id]],Financials[movie_id],Financials[unit],TRUE) -> Billions | M2: =IF(ISNUMBER(I2),"Matched","Missing Finance Data") -> Matched
A3: 102 | B3: Doctor Strange in the Multiverse of Madness | C3: 2022 | D3: Hollywood | E3: 2022 | F3: 7 | G3: Marvel Studios | H3: 5 | I3: =_xlfn.XLOOKUP(Movies_1[[#This Row],[Movie_id]],Financials[movie_id],Financials[budget],"not Avialable") -> 200 | J3: =VLOOKUP(Movies_1[[#This Row],[Movie_id]],Financials[],2,FALSE) -> 200 | K3: =_xlfn.XLOOKUP(Movies_1[[#This Row],[Movie_id]],Financials[movie_id],Financials[revenue],"not avialable") -> 954.8 | L3: =_xlfn.XLOOKUP(Movies_1[[#This Row],[Movie_id]],Financials[movie_id],Financials[unit],TRUE) -> Millions | M3: =IF(ISNUMBER(I3),"Matched","Missing Finance Data") -> Matched
A4: 103 | B4: Thor: The Dark World | C4: 2013 | D4: Hollywood | E4: 2013 | F4: 6.8 | G4: Marvel Studios | H4: 5 | I4: =_xlfn.XLOOKUP(Movies_1[[#This Row],[Movie_id]],Financials[movie_id],Financials[budget],"not Avialable") -> 165 | J4: =VLOOKUP(Movies_1[[#This Row],[Movie_id]],Financials[],2,FALSE) -> 165 | K4: =_xlfn.XLOOKUP(Movies_1[[#This Row],[Movie_id]],Financials[movie_id],Financials[revenue],"not avialable") -> 644.8 | L4: =_xlfn.XLOOKUP(Movies_1[[#This Row],[Movie_id]],Financials[movie_id],Financials[unit],TRUE) -> Millions | M4: =IF(ISNUMBER(I4),"Matched","Missing Finance Data") -> Matched
A5: 104 | B5: Thor: Ragnarok | C5: 2017 | D5: Hollywood | E5: 2017 | F5: 7.9 | G5: Marvel Studios | H5: 5 | I5: =_xlfn.XLOOKUP(Movies_1[[#This Row],[Movie_id]],Financials[movie_id],Financials[budget],"not Avialable") -> 180 | J5: =VLOOKUP(Movies_1[[#This Row],[Movie_id]],Financials[],2,FALSE) -> 180 | K5: =_xlfn.XLOOKUP(Movies_1[[#This Row],[Movie_id]],Financials[movie_id],Financials[revenue],"not avialable") -> 854 | L5: =_xlfn.XLOOKUP(Movies_1[[#This Row],[Movie_id]],Financials[movie_id],Financials[unit],TRUE) -> Millions | M5: =IF(ISNUMBER(I5),"Matched","Missing Finance Data") -> Matched
A6: 105 | B6: Thor: Love and Thunder | C6: 2022 | D6: Hollywood | E6: 2022 | F6: 6.8 | G6: Marvel Studios | H6: 5 | I6: =_xlfn.XLOOKUP(Movies_1[[#This Row],[Movie_id]],Financials[movie_id],Financials[budget],"not Avialable") -> 250 | J6: =VLOOKUP(Movies_1[[#This Row],[Movie_id]],Financials[],2,FALSE) -> 250 | K6: =_xlfn.XLOOKUP(Movies_1[[#This Row],[Movie_id]],Financials[movie_id],Financials[revenue],"not avialable") -> 670 | L6: =_xlfn.XLOOKUP(Movies_1[[#This Row],[Movie_id]],Financials[movie_id],Financials[unit],TRUE) -> Millions | M6: =IF(ISNUMBER(I6),"Matched","Missing Finance Data") -> Matched
A7: 106 | B7: Sholay | C7: 2022 | D7: Bollywood | E7: 1975 | F7: 8.1 | G7: United Producers | H7: 1 | I7: =_xlfn.XLOOKUP(Movies_1[[#This Row],[Movie_id]],Financials[movie_id],Financials[budget],"not Avialable") -> not Avialable | J7: =VLOOKUP(Movies_1[[#This Row],[Movie_id]],Financials[],2,FALSE) -> #N/A | K7: =_xlfn.XLOOKUP(Movies_1[[#This Row],[Movie_id]],Financials[movie_id],Financials[revenue],"not avialable") -> not avialable | L7: =_xlfn.XLOOKUP(Movies_1[[#This Row],[Movie_id]],Financials[movie_id],Financials[unit],TRUE) -> TRUE | M7: =IF(ISNUMBER(I7),"Matched","Missing Finance Data") -> Missing Finance Data
A8: 107 | B8: Dilwale Dulhania Le Jayenge | C8: 2022 | D8: Bollywood | E8: 1995 | F8: 8 | G8: Yash Raj Films | H8: 1 | I8: =_xlfn.XLOOKUP(Movies_1[[#This Row],[Movie_id]],Financials[movie_id],Financials[budget],"not Avialable") -> 400 | J8: =VLOOKUP(Movies_1[[#This Row],[Movie_id]],Financials[],2,FALSE) -> 400 | K8: =_xlfn.XLOOKUP(Movies_1[[#This Row],[Movie_id]],Financials[movie_id],Financials[revenue],"not avialable") -> 2000 | L8: =_xlfn.XLOOKUP(Movies_1[[#This Row],[Movie_id]],Financials[movie_id],Financials[unit],TRUE) -> Millions | M8: =IF(ISNUMBER(I8),"Matched","Missing Finance Data") -> Matched
A9: 108 | B9: 3 Idiots | C9: 2022 | D9: Bollywood | E9: 2009 | F9: 8.4 | G9: Vinod Chopra Films | H9: 1 | I9: =_xlfn.XLOOKUP(Movies_1[[#This Row],[Movie_id]],Financials[movie_id],Financials[budget],"not Avialable") -> 550 | J9: =VLOOKUP(Movies_1[[#This Row],[Movie_id]],Financials[],2,FALSE) -> 550 | K9: =_xlfn.XLOOKUP(Movies_1[[#This Row],[Movie_id]],Financials[movie_id],Financials[revenue],"not avialable") -> 4000 | L9: =_xlfn.XLOOKUP(Movies_1[[#This Row],[Movie_id]],Financials[movie_id],Financials[unit],TRUE) -> Millions | M9: =IF(ISNUMBER(I9),"Matched","Missing Finance Data") -> Matched
A10: 109 | B10: Kabhi Khushi Kabhie Gham | C10: 1975 | D10: Bollywood | E10: 2001 | F10: 7.4 | G10: Dharma Productions | H10: 1 | I10: =_xlfn.XLOOKUP(Movies_1[[#This Row],[Movie_id]],Financials[movie_id],Financials[budget],"not Avialable") -> 390 | J10: =VLOOKUP(Movies_1[[#This Row],[Movie_id]],Financials[],2,FALSE) -> 390 | K10: =_xlfn.XLOOKUP(Movies_1[[#This Row],[Movie_id]],Financials[movie_id],Financials[revenue],"not avialable") -> 1360 | L10: =_xlfn.XLOOKUP(Movies_1[[#This Row],[Movie_id]],Financials[movie_id],Financials[unit],TRUE) -> Millions | M10: =IF(ISNUMBER(I10),"Matched","Missing Finance Data") -> Matched
A11: 110 | B11: Bajirao Mastani | C11: 1995 | D11: Bollywood | E11: 2015 | F11: 7.2 | G11: Not Avialable | H11: 1 | I11: =_xlfn.XLOOKUP(Movies_1[[#This Row],[Movie_id]],Financials[movie_id],Financials[budget],"not Avialable") -> 1.4 | J11: =VLOOKUP(Movies_1[[#This Row],[Movie_id]],Financials[],2,FALSE) -> 1.4 | K11: =_xlfn.XLOOKUP(Movies_1[[#This Row],[Movie_id]],Financials[movie_id],Financials[revenue],"not avialable") -> 3.5 | L11: =_xlfn.XLOOKUP(Movies_1[[#This Row],[Movie_id]],Financials[movie_id],Financials[unit],TRUE) -> Billions | M11: =IF(ISNUMBER(I11),"Matched","Missing Finance Data") -> Matched
A12: 111 | B12: The Shawshank Redemption | C12: 2009 | D12: Hollywood | E12: 1994 | F12: 9.3 | G12: Castle Rock Entertainment | H12: 5 | I12: =_xlfn.XLOOKUP(Movies_1[[#This Row],[Movie_id]],Financials[movie_id],Financials[budget],"not Avialable") -> 25 | J12: =VLOOKUP(Movies_1[[#This Row],[Movie_id]],Financials[],2,FALSE) -> 25 | K12: =_xlfn.XLOOKUP(Movies_1[[#This Row],[Movie_id]],Financials[movie_id],Financials[revenue],"not avialable") -> 73.3 | L12: =_xlfn.XLOOKUP(Movies_1[[#This Row],[Movie_id]],Financials[movie_id],Financials[unit],TRUE) -> Millions | M12: =IF(ISNUMBER(I12),"Matched","Missing Finance Data") -> Matched
A13: 112 | B13: Inception | C13: 2001 | D13: Hollywood | E13: 2010 | F13: 8.8 | G13: Warner Bros. Pictures | H13: 5 | I13: =_xlfn.XLOOKUP(Movies_1[[#This Row],[Movie_id]],Financials[movie_id],Financials[budget],"not Avialable") -> not Avialable | J13: =VLOOKUP(Movies_1[[#This Row],[Movie_id]],Financials[],2,FALSE) -> #N/A | K13: =_xlfn.XLOOKUP(Movies_1[[#This Row],[Movie_id]],Financials[movie_id],Financials[revenue],"not avialable") -> not avialable | L13: =_xlfn.XLOOKUP(Movies_1[[#This Row],[Movie_id]],Financials[movie_id],Financials[unit],TRUE) -> TRUE | M13: =IF(ISNUMBER(I13),"Matched","Missing Finance Data") -> Missing Finance Data
... A42: 140 | B42: Shershaah | C42: 2021 | D42: Bollywood | E42: 2021 | F42: 8.4 | G42: Dharma Productions | H42: 1 | I42: =_xlfn.XLOOKUP(Movies_1[[#This Row],[Movie_id]],Financials[movie_id],Financials[budget],"not Avialable") -> 500 | J42: =VLOOKUP(Movies_1[[#This Row],[Movie_id]],Financials[],2,FALSE) -> 500 | K42: =_xlfn.XLOOKUP(Movies_1[[#This Row],[Movie_id]],Financials[movie_id],Financials[revenue],"not avialable") -> 950 | L42: =_xlfn.XLOOKUP(Movies_1[[#This Row],[Movie_id]],Financials[movie_id],Financials[unit],TRUE) -> Millions | M42: =IF(ISNUMBER(I42),"Matched","Missing Finance Data") -> Matched

Sheet DAY 2
A1: movie_id | B1: budget | C1: revenue | D1: unit | E1: currency | H1: Sales | I1: Tax rate | J1: Tax amount | M1: * | N1: 2 | O1: 3
A2: 101 | B2: 1 | C2: 12.5 | D2: Billions | E2: INR | H2: 1000 | I2: 0.18 | J2: =H2*$I$2 -> 180 | L2: 1 | M2: 10 | N2: =$M2*$N$1 -> 20 | O2: =$L2*$O$1 -> 3
A3: 102 | B3: 200 | C3: 954.8 | D3: Millions | E3: USD | H3: 1500 | J3: =H3*$I$2 -> 270 | L3: 2 | M3: 20 | N3: =$M3*$N$1 -> 40 | O3: =$L3*$O$1 -> 6
A4: 103 | B4: 165 | C4: 644.8 | D4: Millions | E4: USD | H4: 2000 | J4: =H4*$I$2 -> 360 | L4: 3 | M4: 30 | N4: =$M4*$N$1 -> 60 | O4: =$L4*$O$1 -> 9
A5: 104 | B5: 180 | C5: 854 | D5: Millions | E5: USD | H5: 3000 | J5: =H5*$I$2 -> 540 | L5: 4 | M5: 40 | N5: =$M5*$N$1 -> 80 | O5: =$L5*$O$1 -> 12
A6: 105 | B6: 250 | C6: 670 | D6: Millions | E6: USD | L6: 5 | O6: =$L6*$O$1 -> 15
A7: 107 | B7: 400 | C7: 2000 | D7: Millions | E7: INR | L7: 6 | O7: =$L7*$O$1 -> 18
A8: 108 | B8: 550 | C8: 4000 | D8: Millions | E8: INR | L8: 7 | O8: =$L8*$O$1 -> 21
A9: 109 | B9: 390 | C9: 1360 | D9: Millions | E9: INR | L9: 8 | O9: =$L9*$O$1 -> 24
A10: 110 | B10: 1.4 | C10: 3.5 | D10: Billions | E10: INR | L10: 9 | O10: =$L10*$O$1 -> 27
A11: 111 | B11: 25 | C11: 73.3 | D11: Millions | E11: USD | L11: 10 | O11: =$L11*$O$1 -> 30
A12: 113 | B12: 165 | C12: 701.8 | D12: Millions | E12: USD
A13: 114 | B13: 205 | C13: 365.3 | D13: Millions | E13: USD
A14: 115 | B14: 55 | C14: 307.1 | D14: Millions | E14: USD
A15: 116 | B15: 103 | C15: 460.5 | D15: Millions | E15: USD
A16: 117 | B16: 200 | C16: 2202 | D16: Millions | E16: USD
A17: 118 | B17: 3.18 | C17: 3.3 | D17: Millions | E17: USD
A18: 119 | B18: 237 | C18: 2847 | D18: Millions | E18: USD
A19: 120 | B19: 7.2 | C19: 291 | D19: Millions | E19: USD
A20: 121 | B20: 185 | C20: 1006 | D20: Millions | E20: USD
A21: 122 | B21: 22 | C21: 322.2 | D21: Millions | E21: USD
A22: 123 | B22: 63 | C22: 1046 | D22: Millions | E22: USD
A23: 124 | B23: 15.5 | C23: 263.1 | D23: Millions | E23: USD
... A41: 412 | B41: 160 | C41: 836.8 | D41: Millions | E41: USD

Sheet DAY 3
A1: Movie_id | B1: Title | C1: industry | D1: release_year | E1: imdb_rating | F1: studio | G1: language_id | H1: budget | I1: revenue | J1: unit | K1: currency | L1: release_date | M1: Movie_performance | N1: Rating_category | O1: Budget_category
A2: 101 | B2: K.G.F: Chapter 2 | C2: Bollywood | D2: 2022 | E2: 8.4 | F2: Hombale Films | G2: 3 | H2: 1 | I2: 12.5 | J2: Billions | K2: INR | L2: 44665 | M2: {=_xlfn.IFS( Movie_financials[[#This Row],[revenue]]<500,"Average", Movie_financials[[#This Row],[revenue]]<=1000,"Hit", TRUE,"Blockbuster")} -> Average | N2: {=_xlfn.IFS(Movie_financials[[#This Row],[imdb_rating]]<7,"Average",Movie_financials[[#This Row],[imdb_rating]]<=8.5,"Good",TRUE,"Excellent")} -> Good | O2: {=_xlfn.IFS(Movie_financials[[#This Row],[budget]]<50,"Low budget",Movie_financials[[#This Row],[budget]]<=150,"Medium budget",TRUE,"High budget")} -> Low budget
A3: 102 | B3: Doctor Strange in the Multiverse of Madness | C3: Hollywood | D3: 2022 | E3: 7 | F3: Marvel Studios | G3: 5 | H3: 200 | I3: 954.8 | J3: Millions | K3: USD | L3: 44687 | M3: {=_xlfn.IFS( Movie_financials[[#This Row],[revenue]]<500,"Average", Movie_financials[[#This Row],[revenue]]<=1000,"Hit", TRUE,"Blockbuster")} -> Hit | N3: {=_xlfn.IFS(Movie_financials[[#This Row],[imdb_rating]]<7,"Average",Movie_financials[[#This Row],[imdb_rating]]<=8.5,"Good",TRUE,"Excellent")} -> Good | O3: {=_xlfn.IFS(Movie_financials[[#This Row],[budget]]<50,"Low budget",Movie_financials[[#This Row],[budget]]<=150,"Medium budget",TRUE,"High budget")} -> High budget
A4: 103 | B4: Thor: The Dark World | C4: Hollywood | D4: 2013 | E4: 6.8 | F4: Marvel Studios | G4: 5 | H4: 165 | I4: 644.8 | J4: Millions | K4: USD | L4: 41586 | M4: {=_xlfn.IFS( Movie_financials[[#This Row],[revenue]]<500,"Average", Movie_financials[[#This Row],[revenue]]<=1000,"Hit", TRUE,"Blockbuster")} -> Hit | N4: {=_xlfn.IFS(Movie_financials[[#This Row],[imdb_rating]]<7,"Average",Movie_financials[[#This Row],[imdb_rating]]<=8.5,"Good",TRUE,"Excellent")} -> Average | O4: {=_xlfn.IFS(Movie_financials[[#This Row],[budget]]<50,"Low budget",Movie_financials[[#This Row],[budget]]<=150,"Medium budget",TRUE,"High budget")} -> High budget
A5: 104 | B5: Thor: Ragnarok | C5: Hollywood | D5: 2017 | E5: 7.9 | F5: Marvel Studios | G5: 5 | H5: 180 | I5: 854 | J5: Millions | K5: USD | L5: 43042 | M5: {=_xlfn.IFS( Movie_financials[[#This Row],[revenue]]<500,"Average", Movie_financials[[#This Row],[revenue]]<=1000,"Hit", TRUE,"Blockbuster")} -> Hit | N5: {=_xlfn.IFS(Movie_financials[[#This Row],[imdb_rating]]<7,"Average",Movie_financials[[#This Row],[imdb_rating]]<=8.5,"Good",TRUE,"Excellent")} -> Good | O5: {=_xlfn.IFS(Movie_financials[[#This Row],[budget]]<50,"Low budget",Movie_financials[[#This Row],[budget]]<=150,"Medium budget",TRUE,"High budget")} -> High budget
A6: 105 | B6: Thor: Love and Thunder | C6: Hollywood | D6: 2022 | E6: 6.8 | F6: Marvel Studios | G6: 5 | H6: 250 | I6: 670 | J6: Millions | K6: USD | L6: 44750 | M6: {=_xlfn.IFS( Movie_financials[[#This Row],[revenue]]<500,"Average", Movie_financials[[#This Row],[revenue]]<=1000,"Hit", TRUE,"Blockbuster")} -> Hit | N6: {=_xlfn.IFS(Movie_financials[[#This Row],[imdb_rating]]<7,"Average",Movie_financials[[#This Row],[imdb_rating]]<=8.5,"Good",TRUE,"Excellent")} -> Average | O6: {=_xlfn.IFS(Movie_financials[[#This Row],[budget]]<50,"Low budget",Movie_financials[[#This Row],[budget]]<=150,"Medium budget",TRUE,"High budget")} -> High budget
A7: 106 | B7: Sholay | C7: Bollywood | D7: 1975 | E7: 8.1 | F7: United Producers | G7: 1 | L7: 27621 | M7: {=_xlfn.IFS( Movie_financials[[#This Row],[revenue]]<500,"Average", Movie_financials[[#This Row],[revenue]]<=1000,"Hit", TRUE,"Blockbuster")} -> Average | N7: {=_xlfn.IFS(Movie_financials[[#This Row],[imdb_rating]]<7,"Average",Movie_financials[[#This Row],[imdb_rating]]<=8.5,"Good",TRUE,"Excellent")} -> Good | O7: {=_xlfn.IFS(Movie_financials[[#This Row],[budget]]<50,"Low budget",Movie_financials[[#This Row],[budget]]<=150,"Medium budget",TRUE,"High budget")} -> Low budget
A8: 107 | B8: Dilwale Dulhania Le Jayenge | C8: Bollywood | D8: 1995 | E8: 8 | F8: Yash Raj Films | G8: 1 | H8: 400 | I8: 2000 | J8: Millions | K8: INR | L8: 34992 | M8: {=_xlfn.IFS( Movie_financials[[#This Row],[revenue]]<500,"Average", Movie_financials[[#This Row],[revenue]]<=1000,"Hit", TRUE,"Blockbuster")} -> Blockbuster | N8: {=_xlfn.IFS(Movie_financials[[#This Row],[imdb_rating]]<7,"Average",Movie_financials[[#This Row],[imdb_rating]]<=8.5,"Good",TRUE,"Excellent")} -> Good | O8: {=_xlfn.IFS(Movie_financials[[#This Row],[budget]]<50,"Low budget",Movie_financials[[#This Row],[budget]]<=150,"Medium budget",TRUE,"High budget")} -> High budget
A9: 108 | B9: 3 Idiots | C9: Bollywood | D9: 2009 | E9: 8.4 | F9: Vinod Chopra Films | G9: 1 | H9: 550 | I9: 4000 | J9: Millions | K9: INR | L9: 40172 | M9: {=_xlfn.IFS( Movie_financials[[#This Row],[revenue]]<500,"Average", Movie_financials[[#This Row],[revenue]]<=1000,"Hit", TRUE,"Blockbuster")} -> Blockbuster | N9: {=_xlfn.IFS(Movie_financials[[#This Row],[imdb_rating]]<7,"Average",Movie_financials[[#This Row],[imdb_rating]]<=8.5,"Good",TRUE,"Excellent")} -> Good | O9: {=_xlfn.IFS(Movie_financials[[#This Row],[budget]]<50,"Low budget",Movie_financials[[#This Row],[budget]]<=150,"Medium budget",TRUE,"High budget")} -> High budget
A10: 109 | B10: Kabhi Khushi Kabhie Gham | C10: Bollywood | D10: 2001 | E10: 7.4 | F10: Dharma Productions | G10: 1 | H10: 390 | I10: 1360 | J10: Millions | K10: INR | L10: 37239 | M10: {=_xlfn.IFS( Movie_financials[[#This Row],[revenue]]<500,"Average", Movie_financials[[#This Row],[revenue]]<=1000,"Hit", TRUE,"Blockbuster")} -> Blockbuster | N10: {=_xlfn.IFS(Movie_financials[[#This Row],[imdb_rating]]<7,"Average",Movie_financials[[#This Row],[imdb_rating]]<=8.5,"Good",TRUE,"Excellent")} -> Good | O10: {=_xlfn.IFS(Movie_financials[[#This Row],[budget]]<50,"Low budget",Movie_financials[[#This Row],[budget]]<=150,"Medium budget",TRUE,"High budget")} -> High budget
A11: 110 | B11: Bajirao Mastani | C11: Bollywood | D11: 2015 | E11: 7.2 | F11: Not Avialable | G11: 1 | H11: 1 | I11: 3.5 | J11: Billions | K11: INR | L11: 42356 | M11: {=_xlfn.IFS( Movie_financials[[#This Row],[revenue]]<500,"Average", Movie_financials[[#This Row],[revenue]]<=1000,"Hit", TRUE,"Blockbuster")} -> Average | N11: {=_xlfn.IFS(Movie_financials[[#This Row],[imdb_rating]]<7,"Average",Movie_financials[[#This Row],[imdb_rating]]<=8.5,"Good",TRUE,"Excellent")} -> Good | O11: {=_xlfn.IFS(Movie_financials[[#This Row],[budget]]<50,"Low budget",Movie_financials[[#This Row],[budget]]<=150,"Medium budget",TRUE,"High budget")} -> Low budget
A12: 111 | B12: The Shawshank Redemption | C12: Hollywood | D12: 1994 | E12: 9.3 | F12: Castle Rock Entertainment | G12: 5 | H12: 25 | I12: 73.3 | J12: Millions | K12: USD | L12: 34600 | M12: {=_xlfn.IFS( Movie_financials[[#This Row],[revenue]]<500,"Average", Movie_financials[[#This Row],[revenue]]<=1000,"Hit", TRUE,"Blockbuster")} -> Average | N12: {=_xlfn.IFS(Movie_financials[[#This Row],[imdb_rating]]<7,"Average",Movie_financials[[#This Row],[imdb_rating]]<=8.5,"Good",TRUE,"Excellent")} -> Excellent | O12: {=_xlfn.IFS(Movie_financials[[#This Row],[budget]]<50,"Low budget",Movie_financials[[#This Row],[budget]]<=150,"Medium budget",TRUE,"High budget")} -> Low budget
A13: 113 | B13: Interstellar | C13: Hollywood | D13: 2014 | E13: 8.6 | F13: Warner Bros. Pictures | G13: 5 | H13: 165 | I13: 701.8 | J13: Millions | K13: USD | L13: 41836 | M13: {=_xlfn.IFS( Movie_financials[[#This Row],[revenue]]<500,"Average", Movie_financials[[#This Row],[revenue]]<=1000,"Hit", TRUE,"Blockbuster")} -> Hit | N13: {=_xlfn.IFS(Movie_financials[[#This Row],[imdb_rating]]<7,"Average",Movie_financials[[#This Row],[imdb_rating]]<=8.5,"Good",TRUE,"Excellent")} -> Excellent | O13: {=_xlfn.IFS(Movie_financials[[#This Row],[budget]]<50,"Low budget",Movie_financials[[#This Row],[budget]]<=150,"Medium budget",TRUE,"High budget")} -> High budget
A14: 112 | B14: Inception | C14: Hollywood | D14: 2010 | E14: 8.8 | F14: Warner Bros. Pictures | G14: 5 | L14: 40489 | M14: {=_xlfn.IFS( Movie_financials[[#This Row],[revenue]]<500,"Average", Movie_financials[[#This Row],[revenue]]<=1000,"Hit", TRUE,"Blockbuster")} -> Average | N14: {=_xlfn.IFS(Movie_financials[[#This Row],[imdb_rating]]<7,"Average",Movie_financials[[#This Row],[imdb_rating]]<=8.5,"Good",TRUE,"Excellent")} -> Excellent | O14: {=_xlfn.IFS(Movie_financials[[#This Row],[budget]]<50,"Low budget",Movie_financials[[#This Row],[budget]]<=150,"Medium budget",TRUE,"High budget")} -> Low budget
A15: 115 | B15: The Pursuit of Happyness | C15: Hollywood | D15: 2006 | E15: 8 | F15: Columbia Pictures | G15: 5 | H15: 55 | I15: 307.1 | J15: Millions | K15: USD | L15: 39066 | M15: {=_xlfn.IFS( Movie_financials[[#This Row],[revenue]]<500,"Average", Movie_financials[[#This Row],[revenue]]<=1000,"Hit", TRUE,"Blockbuster")} -> Average | N15: {=_xlfn.IFS(Movie_financials[[#This Row],[imdb_rating]]<7,"Average",Movie_financials[[#This Row],[imdb_rating]]<=8.5,"Good",TRUE,"Excellent")} -> Good | O15: {=_xlfn.IFS(Movie_financials[[#This Row],[budget]]<50,"Low budget",Movie_financials[[#This Row],[budget]]<=150,"Medium budget",TRUE,"High budget")} -> Medium budget
A16: 116 | B16: Gladiator | C16: Hollywood | D16: 2000 | E16: 8.5 | F16: Universal Pictures | G16: 5 | H16: 103 | I16: 460.5 | J16: Millions | K16: USD | L16: 36651 | M16: {=_xlfn.IFS( Movie_financials[[#This Row],[revenue]]<500,"Average", Movie_financials[[#This Row],[revenue]]<=1000,"Hit", TRUE,"Blockbuster")} -> Average | N16: {=_xlfn.IFS(Movie_financials[[#This Row],[imdb_rating]]<7,"Average",Movie_financials[[#This Row],[imdb_rating]]<=8.5,"Good",TRUE,"Excellent")} -> Good | O16: {=_xlfn.IFS(Movie_financials[[#This Row],[budget]]<50,"Low budget",Movie_financials[[#This Row],[budget]]<=150,"Medium budget",TRUE,"High budget")} -> Medium budget
A17: 117 | B17: Titanic | C17: Hollywood | D17: 1997 | E17: 7.9 | F17: Paramount Pictures | G17: 5 | H17: 200 | I17: 2202 | J17: Millions | K17: USD | L17: 35783 | M17: {=_xlfn.IFS( Movie_financials[[#This Row],[revenue]]<500,"Average", Movie_financials[[#This Row],[revenue]]<=1000,"Hit", TRUE,"Blockbuster")} -> Blockbuster | N17: {=_xlfn.IFS(Movie_financials[[#This Row],[imdb_rating]]<7,"Average",Movie_financials[[#This Row],[imdb_rating]]<=8.5,"Good",TRUE,"Excellent")} -> Good | O17: {=_xlfn.IFS(Movie_financials[[#This Row],[budget]]<50,"Low budget",Movie_financials[[#This Row],[budget]]<=150,"Medium budget",TRUE,"High budget")} -> High budget
A18: 118 | B18: It's a Wonderful Life | C18: Hollywood | D18: 1946 | E18: 8.6 | F18: Liberty Films | G18: 5 | H18: 3 | I18: 3.3 | J18: Millions | K18: USD | L18: 17156 | M18: {=_xlfn.IFS( Movie_financials[[#This Row],[revenue]]<500,"Average", Movie_financials[[#This Row],[revenue]]<=1000,"Hit", TRUE,"Blockbuster")} -> Average | N18: {=_xlfn.IFS(Movie_financials[[#This Row],[imdb_rating]]<7,"Average",Movie_financials[[#This Row],[imdb_rating]]<=8.5,"Good",TRUE,"Excellent")} -> Excellent | O18: {=_xlfn.IFS(Movie_financials[[#This Row],[budget]]<50,"Low budget",Movie_financials[[#This Row],[budget]]<=150,"Medium budget",TRUE,"High budget")} -> Low budget
A19: 119 | B19: Avatar | C19: Hollywood | D19: 2009 | E19: 7.8 | F19: 20th Century Fox | G19: 5 | H19: 237 | I19: 2847 | J19: Millions | K19: USD | L19: 40165 | M19: {=_xlfn.IFS( Movie_financials[[#This Row],[revenue]]<500,"Average", Movie_financials[[#This Row],[revenue]]<=1000,"Hit", TRUE,"Blockbuster")} -> Blockbuster | N19: {=_xlfn.IFS(Movie_financials[[#This Row],[imdb_rating]]<7,"Average",Movie_financials[[#This Row],[imdb_rating]]<=8.5,"Good",TRUE,"Excellent")} -> Good | O19: {=_xlfn.IFS(Movie_financials[[#This Row],[budget]]<50,"Low budget",Movie_financials[[#This Row],[budget]]<=150,"Medium budget",TRUE,"High budget")} -> High budget
A20: 120 | B20: The Godfather | C20: Hollywood | D20: 1972 | E20: 9.2 | F20: Paramount Pictures | G20: 5 | H20: 7 | I20: 291 | J20: Millions | K20: USD | L20: 26382 | M20: {=_xlfn.IFS( Movie_financials[[#This Row],[revenue]]<500,"Average", Movie_financials[[#This Row],[revenue]]<=1000,"Hit", TRUE,"Blockbuster")} -> Average | N20: {=_xlfn.IFS(Movie_financials[[#This Row],[imdb_rating]]<7,"Average",Movie_financials[[#This Row],[imdb_rating]]<=8.5,"Good",TRUE,"Excellent")} -> Excellent | O20: {=_xlfn.IFS(Movie_financials[[#This Row],[budget]]<50,"Low budget",Movie_financials[[#This Row],[budget]]<=150,"Medium budget",TRUE,"High budget")} -> Low budget
A21: 121 | B21: The Dark Knight | C21: Hollywood | D21: 2008 | E21: 9 | F21: Syncopy | G21: 5 | H21: 185 | I21: 1006 | J21: Millions | K21: USD | L21: 39647 | M21: {=_xlfn.IFS( Movie_financials[[#This Row],[revenue]]<500,"Average", Movie_financials[[#This Row],[revenue]]<=1000,"Hit", TRUE,"Blockbuster")} -> Blockbuster | N21: {=_xlfn.IFS(Movie_financials[[#This Row],[imdb_rating]]<7,"Average",Movie_financials[[#This Row],[imdb_rating]]<=8.5,"Good",TRUE,"Excellent")} -> Excellent | O21: {=_xlfn.IFS(Movie_financials[[#This Row],[budget]]<50,"Low budget",Movie_financials[[#This Row],[budget]]<=150,"Medium budget",TRUE,"High budget")} -> High budget
A22: 122 | B22: Schindler's List | C22: Hollywood | D22: 1993 | E22: 9 | F22: Universal Pictures | G22: 5 | H22: 22 | I22: 322.2 | J22: Millions | K22: USD | L22: 34004 | M22: {=_xlfn.IFS( Movie_financials[[#This Row],[revenue]]<500,"Average", Movie_financials[[#This Row],[revenue]]<=1000,"Hit", TRUE,"Blockbuster")} -> Average | N22: {=_xlfn.IFS(Movie_financials[[#This Row],[imdb_rating]]<7,"Average",Movie_financials[[#This Row],[imdb_rating]]<=8.5,"Good",TRUE,"Excellent")} -> Excellent | O22: {=_xlfn.IFS(Movie_financials[[#This Row],[budget]]<50,"Low budget",Movie_financials[[#This Row],[budget]]<=150,"Medium budget",TRUE,"High budget")} -> Low budget
A23: 123 | B23: Jurassic Park | C23: Hollywood | D23: 1993 | E23: 8.2 | F23: Universal Pictures | G23: 5 | H23: 63 | I23: 1046 | J23: Millions | K23: USD | L23: 34131 | M23: {=_xlfn.IFS( Movie_financials[[#This Row],[revenue]]<500,"Average", Movie_financials[[#This Row],[revenue]]<=1000,"Hit", TRUE,"Blockbuster")} -> Blockbuster | N23: {=_xlfn.IFS(Movie_financials[[#This Row],[imdb_rating]]<7,"Average",Movie_financials[[#This Row],[imdb_rating]]<=8.5,"Good",TRUE,"Excellent")} -> Good | O23: {=_xlfn.IFS(Movie_financials[[#This Row],[budget]]<50,"Low budget",Movie_financials[[#This Row],[budget]]<=150,"Medium budget",TRUE,"High budget")} -> Medium budget
A24: 124 | B24: Parasite | C24: Hollywood | D24: 2019 | E24: 8.5 | F24: Not Avialable | G24: 5 | H24: 16 | I24: 263.1 | J24: Millions | K24: USD | L24: 43615 | M24: {=_xlfn.IFS( Movie_financials[[#This Row],[revenue]]<500,"Average", Movie_financials[[#This Row],[revenue]]<=1000,"Hit", TRUE,"Blockbuster")} -> Average | N24: {=_xlfn.IFS(Movie_financials[[#This Row],[imdb_rating]]<7,"Average",Movie_financials[[#This Row],[imdb_rating]]<=8.5,"Good",TRUE,"Excellent")} -> Good | O24: {=_xlfn.IFS(Movie_financials[[#This Row],[budget]]<50,"Low budget",Movie_financials[[#This Row],[budget]]<=150,"Medium budget",TRUE,"High budget")} -> Low budget
A25: 125 | B25: Avengers: Endgame | C25: Hollywood | D25: 2019 | E25: 8.4 | F25: Marvel Studios | G25: 5 | H25: 400 | I25: 2798 | J25: Millions | K25: USD | L25: 43584 | M25: {=_xlfn.IFS( Movie_financials[[#This Row],[revenue]]<500,"Average", Movie_financials[[#This Row],[revenue]]<=1000,"Hit", TRUE,"Blockbuster")} -> Blockbuster | N25: {=_xlfn.IFS(Movie_financials[[#This Row],[imdb_rating]]<7,"Average",Movie_financials[[#This Row],[imdb_rating]]<=8.5,"Good",TRUE,"Excellent")} -> Good | O25: {=_xlfn.IFS(Movie_financials[[#This Row],[budget]]<50,"Low budget",Movie_financials[[#This Row],[budget]]<=150,"Medium budget",TRUE,"High budget")} -> High budget
A26: 126 | B26: Avengers: Infinity War | C26: Hollywood | D26: 2018 | E26: 8.4 | F26: Marvel Studios | G26: 5 | H26: 400 | I26: 2048 | J26: Millions | K26: USD | L26: 43217 | M26: {=_xlfn.IFS( Movie_financials[[#This Row],[revenue]]<500,"Average", Movie_financials[[#This Row],[revenue]]<=1000,"Hit", TRUE,"Blockbuster")} -> Blockbuster | N26: {=_xlfn.IFS(Movie_financials[[#This Row],[imdb_rating]]<7,"Average",Movie_financials[[#This Row],[imdb_rating]]<=8.5,"Good",TRUE,"Excellent")} -> Good | O26: {=_xlfn.IFS(Movie_financials[[#This Row],[budget]]<50,"Low budget",Movie_financials[[#This Row],[budget]]<=150,"Medium budget",TRUE,"High budget")} -> High budget
... A40: 140 | B40: Shershaah | C40: Bollywood | D40: 2021 | E40: 8.4 | F40: Dharma Productions | G40: 1 | H40: 500 | I40: 950 | J40: Millions | K40: INR | L40: 44420 | M40: {=_xlfn.IFS( Movie_financials[[#This Row],[revenue]]<500,"Average", Movie_financials[[#This Row],[revenue]]<=1000,"Hit", TRUE,"Blockbuster")} -> Hit | N40: {=_xlfn.IFS(Movie_financials[[#This Row],[imdb_rating]]<7,"Average",Movie_financials[[#This Row],[imdb_rating]]<=8.5,"Good",TRUE,"Excellent")} -> Good | O40: {=_xlfn.IFS(Movie_financials[[#This Row],[budget]]<50,"Low budget",Movie_financials[[#This Row],[budget]]<=150,"Medium budget",TRUE,"High budget")} -> High budget

Sheet DAY 4
A2: Text functions in Excel
A4: Studio_number | B4: Extracted_studio_number | C4: Trim checking | D4: value checking
A5: Studio- 101 | B5: =VALUE(TRIM(RIGHT(Table9[[#This Row],[Studio_number]],LEN(Table9[[#This Row],[Studio_number]])-FIND("-",Table9[[#This Row],[Studio_number]],6)))) -> 101 | C5: =LEN(Table9[[#This Row],[Extracted_studio_number]]) -> 3 | D5: =ISNUMBER(Table9[[#This Row],[Extracted_studio_number]]) -> TRUE
A6: Studio- 102 | B6: =VALUE(TRIM(RIGHT(Table9[[#This Row],[Studio_number]],LEN(Table9[[#This Row],[Studio_number]])-FIND("-",Table9[[#This Row],[Studio_number]],6)))) -> 102 | C6: =LEN(Table9[[#This Row],[Extracted_studio_number]]) -> 3 | D6: =ISNUMBER(Table9[[#This Row],[Extracted_studio_number]]) -> TRUE
A7: Studio-103 | B7: =VALUE(TRIM(RIGHT(Table9[[#This Row],[Studio_number]],LEN(Table9[[#This Row],[Studio_number]])-FIND("-",Table9[[#This Row],[Studio_number]],6)))) -> 103 | C7: =LEN(Table9[[#This Row],[Extracted_studio_number]]) -> 3 | D7: =ISNUMBER(Table9[[#This Row],[Extracted_studio_number]]) -> TRUE
A8: Studio-104 | B8: =VALUE(TRIM(RIGHT(Table9[[#This Row],[Studio_number]],LEN(Table9[[#This Row],[Studio_number]])-FIND("-",Table9[[#This Row],[Studio_number]],6)))) -> 104 | C8: =LEN(Table9[[#This Row],[Extracted_studio_number]]) -> 3 | D8: =ISNUMBER(Table9[[#This Row],[Extracted_studio_number]]) -> TRUE
A9: Studio-105 | B9: =VALUE(TRIM(RIGHT(Table9[[#This Row],[Studio_number]],LEN(Table9[[#This Row],[Studio_number]])-FIND("-",Table9[[#This Row],[Studio_number]],6)))) -> 105 | C9: =LEN(Table9[[#This Row],[Extracted_studio_number]]) -> 3 | D9: =ISNUMBER(Table9[[#This Row],[Extracted_studio_number]]) -> TRUE
A10: Studio-106 | B10: =VALUE(TRIM(RIGHT(Table9[[#This Row],[Studio_number]],LEN(Table9[[#This Row],[Studio_number]])-FIND("-",Table9[[#This Row],[Studio_number]],6)))) -> 106 | C10: =LEN(Table9[[#This Row],[Extracted_studio_number]]) -> 3 | D10: =ISNUMBER(Table9[[#This Row],[Extracted_studio_number]]) -> TRUE
A11: Studio-107 | B11: =VALUE(TRIM(RIGHT(Table9[[#This Row],[Studio_number]],LEN(Table9[[#This Row],[Studio_number]])-FIND("-",Table9[[#This Row],[Studio_number]],6)))) -> 107 | C11: =LEN(Table9[[#This Row],[Extracted_studio_number]]) -> 3 | D11: =ISNUMBER(Table9[[#This Row],[Extracted_studio_number]]) -> TRUE
A12: Studio-108 | B12: =VALUE(TRIM(RIGHT(Table9[[#This Row],[Studio_number]],LEN(Table9[[#This Row],[Studio_number]])-FIND("-",Table9[[#This Row],[Studio_number]],6)))) -> 108 | C12: =LEN(Table9[[#This Row],[Extracted_studio_number]]) -> 3 | D12: =ISNUMBER(Table9[[#This Row],[Extracted_studio_number]]) -> TRUE
A13: Studio-109 | B13: =VALUE(TRIM(RIGHT(Table9[[#This Row],[Studio_number]],LEN(Table9[[#This Row],[Studio_number]])-FIND("-",Table9[[#This Row],[Studio_number]],6)))) -> 109 | C13: =LEN(Table9[[#This Row],[Extracted_studio_number]]) -> 3 | D13: =ISNUMBER(Table9[[#This Row],[Extracted_studio_number]]) -> TRUE
A14: Studio-110 | B14: =VALUE(TRIM(RIGHT(Table9[[#This Row],[Studio_number]],LEN(Table9[[#This Row],[Studio_number]])-FIND("-",Table9[[#This Row],[Studio_number]],6)))) -> 110 | C14: =LEN(Table9[[#This Row],[Extracted_studio_number]]) -> 3 | D14: =ISNUMBER(Table9[[#This Row],[Extracted_studio_number]]) -> TRUE
A15: Studio-1111 | B15: =VALUE(TRIM(RIGHT(Table9[[#This Row],[Studio_number]],LEN(Table9[[#This Row],[Studio_number]])-FIND("-",Table9[[#This Row],[Studio_number]],6)))) -> 1111 | C15: =LEN(Table9[[#This Row],[Extracted_studio_number]]) -> 4 | D15: =ISNUMBER(Table9[[#This Row],[Extracted_studio_number]]) -> TRUE
A16: Studio-1112 | B16: =VALUE(TRIM(RIGHT(Table9[[#This Row],[Studio_number]],LEN(Table9[[#This Row],[Studio_number]])-FIND("-",Table9[[#This Row],[Studio_number]],6)))) -> 1112 | C16: =LEN(Table9[[#This Row],[Extracted_studio_number]]) -> 4 | D16: =ISNUMBER(Table9[[#This Row],[Extracted_studio_number]]) -> TRUE
... A22: Studio-118 | B22: =VALUE(TRIM(RIGHT(Table9[[#This Row],[Studio_number]],LEN(Table9[[#This Row],[Studio_number]])-FIND("-",Table9[[#This Row],[Studio_number]],6)))) -> 118 | C22: =LEN(Table9[[#This Row],[Extracted_studio_number]]) -> 3 | D22: =ISNUMBER(Table9[[#This Row],[Extracted_studio_number]]) -> TRUE

Sheet DAY 5
A1: Movie_id | B1: Title | C1: industry | D1: release_year | E1: imdb_rating | F1: studio | G1: language_id | H1: budget | I1: revenue | J1: unit | K1: currency | L1: release_date | M1: Movie_performance | N1: Rating_category | O1: Budget_category | P1: Movie_age | Q1: Movie_age(years) | R1: Movie_era | S1: profit_category | T1: Imdb_grade | U1: revenue_category | V1: Status
A2: 101 | B2: K.G.F: Chapter 2 | C2: Bollywood | D2: 2022 | E2: 8.4 | F2: Hombale Films | G2: 3 | H2: 1 | I2: 12.5 | J2: Billions | K2: INR | L2: 44665 | M2: {=_xlfn.IFS( Movie_financials__with_release_date[[#This Row],[revenue]]<500,"Average", Movie_financials__with_release_date[[#This Row],[revenue]]<=1000,"Hit", TRUE,"Blockbuster")} -> Average | N2: {=_xlfn.IFS(Movie_financials__with_release_date[[#This Row],[imdb_rating]]<7,"Average",Movie_financials__with_release_date[[#This Row],[imdb_rating]]<=8.5,"Good",TRUE,"Excellent")} -> Good | O2: {=_xlfn.IFS(Movie_financials__with_release_date[[#This Row],[budget]]<50,"Low budget",Movie_financials__with_release_date[[#This Row],[budget]]<=150,"Medium budget",TRUE,"High budget")} -> Low budget | P2: =DATEDIF(Movie_financials__with_release_date[[#This Row],[release_date]],TODAY(),"Y")& "years"& DATEDIF(Movie_financials__with_release_date[[#This Row],[release_date]],TODAY(),"YM")& "months" -> 4years3months | Q2: =DATEDIF(Movie_financials__with_release_date[[#This Row],[release_date]],TODAY(),"Y") -> 4 | R2: {=_xlfn.IFS(Movie_financials__with_release_date[[#This Row],[Movie_age(years)]]<5,"New Release",Movie_financials__with_release_date[[#This Row],[Movie_age(years)]]<=15,"Modern Classic", TRUE,"Classic" )} -> New Release | S2: {=_xlfn.IFS(Movie_financials__with_release_date[[#This Row],[revenue]]>Movie_financials__with_release_date[[#This Row],[budget]]*3,"Highly Profitable", Movie_financials__with_release_date[[#This Row],[revenue]]>Movie_financials__with_release_date[[#This Row],[budget]],"Profitable", TRUE,"Low Profit")} -> Highly Profitable | T2: {=_xlfn.IFS(Movie_financials__with_release_date[[#This Row],[imdb_rating]]>=9,"A+", Movie_financials__with_release_date[[#This Row],[imdb_rating]]>=8,"A", Movie_financials__with_release_date[[#This Row],[imdb_rating]]>=7,"B", TRUE,"C")} -> A | U2: {=_xlfn.IFS(Movie_financials__with_release_date[[#This Row],[revenue]]>=2000,"Mega Hit", Movie_financials__with_release_date[[#This Row],[revenue]]>=1000,"Super Hit", Movie_financials__with_release_date[[#This Row],[revenue]]>=500,"Hit", TRUE,"Average")} -> Average | V2: =IF(AND(Movie_financials__with_release_date[[#This Row],[budget]]>=200,Movie_financials__with_release_date[[#This Row],[profit_category]]="Low Profit"),"⚠ Review","OK") -> OK
A3: 102 | B3: Doctor Strange in the Multiverse of Madness | C3: Hollywood | D3: 2022 | E3: 7 | F3: Marvel Studios | G3: 5 | H3: 200 | I3: 954.8 | J3: Millions | K3: USD | L3: 44687 | M3: {=_xlfn.IFS( Movie_financials__with_release_date[[#This Row],[revenue]]<500,"Average", Movie_financials__with_release_date[[#This Row],[revenue]]<=1000,"Hit", TRUE,"Blockbuster")} -> Hit | N3: {=_xlfn.IFS(Movie_financials__with_release_date[[#This Row],[imdb_rating]]<7,"Average",Movie_financials__with_release_date[[#This Row],[imdb_rating]]<=8.5,"Good",TRUE,"Excellent")} -> Good | O3: {=_xlfn.IFS(Movie_financials__with_release_date[[#This Row],[budget]]<50,"Low budget",Movie_financials__with_release_date[[#This Row],[budget]]<=150,"Medium budget",TRUE,"High budget")} -> High budget | P3: =DATEDIF(Movie_financials__with_release_date[[#This Row],[release_date]],TODAY(),"Y")& "years"& DATEDIF(Movie_financials__with_release_date[[#This Row],[release_date]],TODAY(),"YM")& "months" -> 4years2months | Q3: =DATEDIF(Movie_financials__with_release_date[[#This Row],[release_date]],TODAY(),"Y") -> 4 | R3: {=_xlfn.IFS(Movie_financials__with_release_date[[#This Row],[Movie_age(years)]]<5,"New Release",Movie_financials__with_release_date[[#This Row],[Movie_age(years)]]<=15,"Modern Classic", TRUE,"Classic" )} -> New Release | S3: {=_xlfn.IFS(Movie_financials__with_release_date[[#This Row],[revenue]]>Movie_financials__with_release_date[[#This Row],[budget]]*3,"Highly Profitable", Movie_financials__with_release_date[[#This Row],[revenue]]>Movie_financials__with_release_date[[#This Row],[budget]],"Profitable", TRUE,"Low Profit")} -> Highly Profitable | T3: {=_xlfn.IFS(Movie_financials__with_release_date[[#This Row],[imdb_rating]]>=9,"A+", Movie_financials__with_release_date[[#This Row],[imdb_rating]]>=8,"A", Movie_financials__with_release_date[[#This Row],[imdb_rating]]>=7,"B", TRUE,"C")} -> B | U3: {=_xlfn.IFS(Movie_financials__with_release_date[[#This Row],[revenue]]>=2000,"Mega Hit", Movie_financials__with_release_date[[#This Row],[revenue]]>=1000,"Super Hit", Movie_financials__with_release_date[[#This Row],[revenue]]>=500,"Hit", TRUE,"Average")} -> Hit | V3: =IF(AND(Movie_financials__with_release_date[[#This Row],[budget]]>=200,Movie_financials__with_release_date[[#This Row],[profit_category]]="Low Profit"),"⚠ Review","OK") -> OK
A4: 103 | B4: Thor: The Dark World | C4: Hollywood | D4: 2013 | E4: 6.8 | F4: Marvel Studios | G4: 5 | H4: 165 | I4: 644.8 | J4: Millions | K4: USD | L4: 41586 | M4: {=_xlfn.IFS( Movie_financials__with_release_date[[#This Row],[revenue]]<500,"Average", Movie_financials__with_release_date[[#This Row],[revenue]]<=1000,"Hit", TRUE,"Blockbuster")} -> Hit | N4: {=_xlfn.IFS(Movie_financials__with_release_date[[#This Row],[imdb_rating]]<7,"Average",Movie_financials__with_release_date[[#This Row],[imdb_rating]]<=8.5,"Good",TRUE,"Excellent")} -> Average | O4: {=_xlfn.IFS(Movie_financials__with_release_date[[#This Row],[budget]]<50,"Low budget",Movie_financials__with_release_date[[#This Row],[budget]]<=150,"Medium budget",TRUE,"High budget")} -> High budget | P4: =DATEDIF(Movie_financials__with_release_date[[#This Row],[release_date]],TODAY(),"Y")& "years"& DATEDIF(Movie_financials__with_release_date[[#This Row],[release_date]],TODAY(),"YM")& "months" -> 12years8months | Q4: =DATEDIF(Movie_financials__with_release_date[[#This Row],[release_date]],TODAY(),"Y") -> 12 | R4: {=_xlfn.IFS(Movie_financials__with_release_date[[#This Row],[Movie_age(years)]]<5,"New Release",Movie_financials__with_release_date[[#This Row],[Movie_age(years)]]<=15,"Modern Classic", TRUE,"Classic" )} -> Modern Classic | S4: {=_xlfn.IFS(Movie_financials__with_release_date[[#This Row],[revenue]]>Movie_financials__with_release_date[[#This Row],[budget]]*3,"Highly Profitable", Movie_financials__with_release_date[[#This Row],[revenue]]>Movie_financials__with_release_date[[#This Row],[budget]],"Profitable", TRUE,"Low Profit")} -> Highly Profitable | T4: {=_xlfn.IFS(Movie_financials__with_release_date[[#This Row],[imdb_rating]]>=9,"A+", Movie_financials__with_release_date[[#This Row],[imdb_rating]]>=8,"A", Movie_financials__with_release_date[[#This Row],[imdb_rating]]>=7,"B", TRUE,"C")} -> C | U4: {=_xlfn.IFS(Movie_financials__with_release_date[[#This Row],[revenue]]>=2000,"Mega Hit", Movie_financials__with_release_date[[#This Row],[revenue]]>=1000,"Super Hit", Movie_financials__with_release_date[[#This Row],[revenue]]>=500,"Hit", TRUE,"Average")} -> Hit | V4: =IF(AND(Movie_financials__with_release_date[[#This Row],[budget]]>=200,Movie_financials__with_release_date[[#This Row],[profit_category]]="Low Profit"),"⚠ Review","OK") -> OK
A5: 104 | B5: Thor: Ragnarok | C5: Hollywood | D5: 2017 | E5: 7.9 | F5: Marvel Studios | G5: 5 | H5: 180 | I5: 854 | J5: Millions | K5: USD | L5: 43042 | M5: {=_xlfn.IFS( Movie_financials__with_release_date[[#This Row],[revenue]]<500,"Average", Movie_financials__with_release_date[[#This Row],[revenue]]<=1000,"Hit", TRUE,"Blockbuster")} -> Hit | N5: {=_xlfn.IFS(Movie_financials__with_release_date[[#This Row],[imdb_rating]]<7,"Average",Movie_financials__with_release_date[[#This Row],[imdb_rating]]<=8.5,"Good",TRUE,"Excellent")} -> Good | O5: {=_xlfn.IFS(Movie_financials__with_release_date[[#This Row],[budget]]<50,"Low budget",Movie_financials__with_release_date[[#This Row],[budget]]<=150,"Medium budget",TRUE,"High budget")} -> High budget | P5: =DATEDIF(Movie_financials__with_release_date[[#This Row],[release_date]],TODAY(),"Y")& "years"& DATEDIF(Movie_financials__with_release_date[[#This Row],[release_date]],TODAY(),"YM")& "months" -> 8years8months | Q5: =DATEDIF(Movie_financials__with_release_date[[#This Row],[release_date]],TODAY(),"Y") -> 8 | R5: {=_xlfn.IFS(Movie_financials__with_release_date[[#This Row],[Movie_age(years)]]<5,"New Release",Movie_financials__with_release_date[[#This Row],[Movie_age(years)]]<=15,"Modern Classic", TRUE,"Classic" )} -> Modern Classic | S5: {=_xlfn.IFS(Movie_financials__with_release_date[[#This Row],[revenue]]>Movie_financials__with_release_date[[#This Row],[budget]]*3,"Highly Profitable", Movie_financials__with_release_date[[#This Row],[revenue]]>Movie_financials__with_release_date[[#This Row],[budget]],"Profitable", TRUE,"Low Profit")} -> Highly Profitable | T5: {=_xlfn.IFS(Movie_financials__with_release_date[[#This Row],[imdb_rating]]>=9,"A+", Movie_financials__with_release_date[[#This Row],[imdb_rating]]>=8,"A", Movie_financials__with_release_date[[#This Row],[imdb_rating]]>=7,"B", TRUE,"C")} -> B | U5: {=_xlfn.IFS(Movie_financials__with_release_date[[#This Row],[revenue]]>=2000,"Mega Hit", Movie_financials__with_release_date[[#This Row],[revenue]]>=1000,"Super Hit", Movie_financials__with_release_date[[#This Row],[revenue]]>=500,"Hit", TRUE,"Average")} -> Hit | V5: =IF(AND(Movie_financials__with_release_date[[#This Row],[budget]]>=200,Movie_financials__with_release_date[[#This Row],[profit_category]]="Low Profit"),"⚠ Review","OK") -> OK
A6: 105 | B6: Thor: Love and Thunder | C6: Hollywood | D6: 2022 | E6: 6.8 | F6: Marvel Studios | G6: 5 | H6: 250 | I6: 670 | J6: Millions | K6: USD | L6: 44750 | M6: {=_xlfn.IFS( Movie_financials__with_release_date[[#This Row],[revenue]]<500,"Average", Movie_financials__with_release_date[[#This Row],[revenue]]<=1000,"Hit", TRUE,"Blockbuster")} -> Hit | N6: {=_xlfn.IFS(Movie_financials__with_release_date[[#This Row],[imdb_rating]]<7,"Average",Movie_financials__with_release_date[[#This Row],[imdb_rating]]<=8.5,"Good",TRUE,"Excellent")} -> Average | O6: {=_xlfn.IFS(Movie_financials__with_release_date[[#This Row],[budget]]<50,"Low budget",Movie_financials__with_release_date[[#This Row],[budget]]<=150,"Medium budget",TRUE,"High budget")} -> High budget | P6: =DATEDIF(Movie_financials__with_release_date[[#This Row],[release_date]],TODAY(),"Y")& "years"& DATEDIF(Movie_financials__with_release_date[[#This Row],[release_date]],TODAY(),"YM")& "months" -> 4years0months | Q6: =DATEDIF(Movie_financials__with_release_date[[#This Row],[release_date]],TODAY(),"Y") -> 4 | R6: {=_xlfn.IFS(Movie_financials__with_release_date[[#This Row],[Movie_age(years)]]<5,"New Release",Movie_financials__with_release_date[[#This Row],[Movie_age(years)]]<=15,"Modern Classic", TRUE,"Classic" )} -> New Release | S6: {=_xlfn.IFS(Movie_financials__with_release_date[[#This Row],[revenue]]>Movie_financials__with_release_date[[#This Row],[budget]]*3,"Highly Profitable", Movie_financials__with_release_date[[#This Row],[revenue]]>Movie_financials__with_release_date[[#This Row],[budget]],"Profitable", TRUE,"Low Profit")} -> Profitable | T6: {=_xlfn.IFS(Movie_financials__with_release_date[[#This Row],[imdb_rating]]>=9,"A+", Movie_financials__with_release_date[[#This Row],[imdb_rating]]>=8,"A", Movie_financials__with_release_date[[#This Row],[imdb_rating]]>=7,"B", TRUE,"C")} -> C | U6: {=_xlfn.IFS(Movie_financials__with_release_date[[#This Row],[revenue]]>=2000,"Mega Hit", Movie_financials__with_release_date[[#This Row],[revenue]]>=1000,"Super Hit", Movie_financials__with_release_date[[#This Row],[revenue]]>=500,"Hit", TRUE,"Average")} -> Hit | V6: =IF(AND(Movie_financials__with_release_date[[#This Row],[budget]]>=200,Movie_financials__with_release_date[[#This Row],[profit_category]]="Low Profit"),"⚠ Review","OK") -> OK
A7: 106 | B7: Sholay | C7: Bollywood | D7: 1975 | E7: 8.1 | F7: United Producers | G7: 1 | L7: 27621 | M7: {=_xlfn.IFS( Movie_financials__with_release_date[[#This Row],[revenue]]<500,"Average", Movie_financials__with_release_date[[#This Row],[revenue]]<=1000,"Hit", TRUE,"Blockbuster")} -> Average | N7: {=_xlfn.IFS(Movie_financials__with_release_date[[#This Row],[imdb_rating]]<7,"Average",Movie_financials__with_release_date[[#This Row],[imdb_rating]]<=8.5,"Good",TRUE,"Excellent")} -> Good | O7: {=_xlfn.IFS(Movie_financials__with_release_date[[#This Row],[budget]]<50,"Low budget",Movie_financials__with_release_date[[#This Row],[budget]]<=150,"Medium budget",TRUE,"High budget")} -> Low budget | P7: =DATEDIF(Movie_financials__with_release_date[[#This Row],[release_date]],TODAY(),"Y")& "years"& DATEDIF(Movie_financials__with_release_date[[#This Row],[release_date]],TODAY(),"YM")& "months" -> 50years11months | Q7: =DATEDIF(Movie_financials__with_release_date[[#This Row],[release_date]],TODAY(),"Y") -> 50 | R7: {=_xlfn.IFS(Movie_financials__with_release_date[[#This Row],[Movie_age(years)]]<5,"New Release",Movie_financials__with_release_date[[#This Row],[Movie_age(years)]]<=15,"Modern Classic", TRUE,"Classic" )} -> Classic | S7: {=_xlfn.IFS(Movie_financials__with_release_date[[#This Row],[revenue]]>Movie_financials__with_release_date[[#This Row],[budget]]*3,"Highly Profitable", Movie_financials__with_release_date[[#This Row],[revenue]]>Movie_financials__with_release_date[[#This Row],[budget]],"Profitable", TRUE,"Low Profit")} -> Low Profit | T7: {=_xlfn.IFS(Movie_financials__with_release_date[[#This Row],[imdb_rating]]>=9,"A+", Movie_financials__with_release_date[[#This Row],[imdb_rating]]>=8,"A", Movie_financials__with_release_date[[#This Row],[imdb_rating]]>=7,"B", TRUE,"C")} -> A | U7: {=_xlfn.IFS(Movie_financials__with_release_date[[#This Row],[revenue]]>=2000,"Mega Hit", Movie_financials__with_release_date[[#This Row],[revenue]]>=1000,"Super Hit", Movie_financials__with_release_date[[#This Row],[revenue]]>=500,"Hit", TRUE,"Average")} -> Average | V7: =IF(AND(Movie_financials__with_release_date[[#This Row],[budget]]>=200,Movie_financials__with_release_date[[#This Row],[profit_category]]="Low Profit"),"⚠ Review","OK") -> OK
A8: 107 | B8: Dilwale Dulhania Le Jayenge | C8: Bollywood | D8: 1995 | E8: 8 | F8: Yash Raj Films | G8: 1 | H8: 400 | I8: 2000 | J8: Millions | K8: INR | L8: 34992 | M8: {=_xlfn.IFS( Movie_financials__with_release_date[[#This Row],[revenue]]<500,"Average", Movie_financials__with_release_date[[#This Row],[revenue]]<=1000,"Hit", TRUE,"Blockbuster")} -> Blockbuster | N8: {=_xlfn.IFS(Movie_financials__with_release_date[[#This Row],[imdb_rating]]<7,"Average",Movie_financials__with_release_date[[#This Row],[imdb_rating]]<=8.5,"Good",TRUE,"Excellent")} -> Good | O8: {=_xlfn.IFS(Movie_financials__with_release_date[[#This Row],[budget]]<50,"Low budget",Movie_financials__with_release_date[[#This Row],[budget]]<=150,"Medium budget",TRUE,"High budget")} -> High budget | P8: =DATEDIF(Movie_financials__with_release_date[[#This Row],[release_date]],TODAY(),"Y")& "years"& DATEDIF(Movie_financials__with_release_date[[#This Row],[release_date]],TODAY(),"YM")& "months" -> 30years9months | Q8: =DATEDIF(Movie_financials__with_release_date[[#This Row],[release_date]],TODAY(),"Y") -> 30 | R8: {=_xlfn.IFS(Movie_financials__with_release_date[[#This Row],[Movie_age(years)]]<5,"New Release",Movie_financials__with_release_date[[#This Row],[Movie_age(years)]]<=15,"Modern Classic", TRUE,"Classic" )} -> Classic | S8: {=_xlfn.IFS(Movie_financials__with_release_date[[#This Row],[revenue]]>Movie_financials__with_release_date[[#This Row],[budget]]*3,"Highly Profitable", Movie_financials__with_release_date[[#This Row],[revenue]]>Movie_financials__with_release_date[[#This Row],[budget]],"Profitable", TRUE,"Low Profit")} -> Highly Profitable | T8: {=_xlfn.IFS(Movie_financials__with_release_date[[#This Row],[imdb_rating]]>=9,"A+", Movie_financials__with_release_date[[#This Row],[imdb_rating]]>=8,"A", Movie_financials__with_release_date[[#This Row],[imdb_rating]]>=7,"B", TRUE,"C")} -> A | U8: {=_xlfn.IFS(Movie_financials__with_release_date[[#This Row],[revenue]]>=2000,"Mega Hit", Movie_financials__with_release_date[[#This Row],[revenue]]>=1000,"Super Hit", Movie_financials__with_release_date[[#This Row],[revenue]]>=500,"Hit", TRUE,"Average")} -> Mega Hit | V8: =IF(AND(Movie_financials__with_release_date[[#This Row],[budget]]>=200,Movie_financials__with_release_date[[#This Row],[profit_category]]="Low Profit"),"⚠ Review","OK") -> OK
A9: 108 | B9: 3 Idiots | C9: Bollywood | D9: 2009 | E9: 8.4 | F9: Vinod Chopra Films | G9: 1 | H9: 550 | I9: 4000 | J9: Millions | K9: INR | L9: 40172 | M9: {=_xlfn.IFS( Movie_financials__with_release_date[[#This Row],[revenue]]<500,"Average", Movie_financials__with_release_date[[#This Row],[revenue]]<=1000,"Hit", TRUE,"Blockbuster")} -> Blockbuster | N9: {=_xlfn.IFS(Movie_financials__with_release_date[[#This Row],[imdb_rating]]<7,"Average",Movie_financials__with_release_date[[#This Row],[imdb_rating]]<=8.5,"Good",TRUE,"Excellent")} -> Good | O9: {=_xlfn.IFS(Movie_financials__with_release_date[[#This Row],[budget]]<50,"Low budget",Movie_financials__with_release_date[[#This Row],[budget]]<=150,"Medium budget",TRUE,"High budget")} -> High budget | P9: =DATEDIF(Movie_financials__with_release_date[[#This Row],[release_date]],TODAY(),"Y")& "years"& DATEDIF(Movie_financials__with_release_date[[#This Row],[release_date]],TODAY(),"YM")& "months" -> 16years6months | Q9: =DATEDIF(Movie_financials__with_release_date[[#This Row],[release_date]],TODAY(),"Y") -> 16 | R9: {=_xlfn.IFS(Movie_financials__with_release_date[[#This Row],[Movie_age(years)]]<5,"New Release",Movie_financials__with_release_date[[#This Row],[Movie_age(years)]]<=15,"Modern Classic", TRUE,"Classic" )} -> Classic | S9: {=_xlfn.IFS(Movie_financials__with_release_date[[#This Row],[revenue]]>Movie_financials__with_release_date[[#This Row],[budget]]*3,"Highly Profitable", Movie_financials__with_release_date[[#This Row],[revenue]]>Movie_financials__with_release_date[[#This Row],[budget]],"Profitable", TRUE,"Low Profit")} -> Highly Profitable | T9: {=_xlfn.IFS(Movie_financials__with_release_date[[#This Row],[imdb_rating]]>=9,"A+", Movie_financials__with_release_date[[#This Row],[imdb_rating]]>=8,"A", Movie_financials__with_release_date[[#This Row],[imdb_rating]]>=7,"B", TRUE,"C")} -> A | U9: {=_xlfn.IFS(Movie_financials__with_release_date[[#This Row],[revenue]]>=2000,"Mega Hit", Movie_financials__with_release_date[[#This Row],[revenue]]>=1000,"Super Hit", Movie_financials__with_release_date[[#This Row],[revenue]]>=500,"Hit", TRUE,"Average")} -> Mega Hit | V9: =IF(AND(Movie_financials__with_release_date[[#This Row],[budget]]>=200,Movie_financials__with_release_date[[#This Row],[profit_category]]="Low Profit"),"⚠ Review","OK") -> OK
A10: 109 | B10: Kabhi Khushi Kabhie Gham | C10: Bollywood | D10: 2001 | E10: 7.4 | F10: Dharma Productions | G10: 1 | H10: 390 | I10: 1360 | J10: Millions | K10: INR | L10: 37239 | M10: {=_xlfn.IFS( Movie_financials__with_release_date[[#This Row],[revenue]]<500,"Average", Movie_financials__with_release_date[[#This Row],[revenue]]<=1000,"Hit", TRUE,"Blockbuster")} -> Blockbuster | N10: {=_xlfn.IFS(Movie_financials__with_release_date[[#This Row],[imdb_rating]]<7,"Average",Movie_financials__with_release_date[[#This Row],[imdb_rating]]<=8.5,"Good",TRUE,"Excellent")} -> Good | O10: {=_xlfn.IFS(Movie_financials__with_release_date[[#This Row],[budget]]<50,"Low budget",Movie_financials__with_release_date[[#This Row],[budget]]<=150,"Medium budget",TRUE,"High budget")} -> High budget | P10: =DATEDIF(Movie_financials__with_release_date[[#This Row],[release_date]],TODAY(),"Y")& "years"& DATEDIF(Movie_financials__with_release_date[[#This Row],[release_date]],TODAY(),"YM")& "months" -> 24years7months | Q10: =DATEDIF(Movie_financials__with_release_date[[#This Row],[release_date]],TODAY(),"Y") -> 24 | R10: {=_xlfn.IFS(Movie_financials__with_release_date[[#This Row],[Movie_age(years)]]<5,"New Release",Movie_financials__with_release_date[[#This Row],[Movie_age(years)]]<=15,"Modern Classic", TRUE,"Classic" )} -> Classic | S10: {=_xlfn.IFS(Movie_financials__with_release_date[[#This Row],[revenue]]>Movie_financials__with_release_date[[#This Row],[budget]]*3,"Highly Profitable", Movie_financials__with_release_date[[#This Row],[revenue]]>Movie_financials__with_release_date[[#This Row],[budget]],"Profitable", TRUE,"Low Profit")} -> Highly Profitable | T10: {=_xlfn.IFS(Movie_financials__with_release_date[[#This Row],[imdb_rating]]>=9,"A+", Movie_financials__with_release_date[[#This Row],[imdb_rating]]>=8,"A", Movie_financials__with_release_date[[#This Row],[imdb_rating]]>=7,"B", TRUE,"C")} -> B | U10: {=_xlfn.IFS(Movie_financials__with_release_date[[#This Row],[revenue]]>=2000,"Mega Hit", Movie_financials__with_release_date[[#This Row],[revenue]]>=1000,"Super Hit", Movie_financials__with_release_date[[#This Row],[revenue]]>=500,"Hit", TRUE,"Average")} -> Super Hit | V10: =IF(AND(Movie_financials__with_release_date[[#This Row],[budget]]>=200,Movie_financials__with_release_date[[#This Row],[profit_category]]="Low Profit"),"⚠ Review","OK") -> OK
